Workbook

Sheet Dados
A1: Estudante | B1: Perfil | C1: Tipo de Aplicação
A2: Gabriela | B2: Conservador | C2: Poupança
A3: Luiz Felipe | B3: Conservador | C3: Poupança
A4: Patrícia | B4: Conservador | C4: Poupança
A5: Gustavo | B5: Conservador | C5: Poupança
A6: Letícia | B6: Conservador | C6: Poupança
A7: Ovídio | B7: Conservador | C7: Poupança
A8: Leonor | B8: Conservador | C8: Poupança
A9: Dalila | B9: Conservador | C9: Poupança
A10: Antônio | B10: Conservador | C10: CDB
A11: Júlia | B11: Conservador | C11: CDB
A12: Roberto | B12: Conservador | C12: CDB
... A101: Estela | B101: Agressivo | C101: Ações

Sheet Anacor
A1: Frequências absolutas observadas | I1: Fávero, Luiz Paulo; Belfiore, Patrícia. (2024). Manual de análise de dados: estatística e machine learning com Excel®, SPSS®, Stata®, R® e Python®. 2 ed. Rio de Janeiro: LTC.
C3: Tipo de Aplicação
C4: Ações | D4: CDB | E4: Poupança | F4: Total
A5: Perfil | B5: Agressivo | C5: =+COUNTIFS(Dados!$B:$B,Anacor!$B5,Dados!$C:$C,Anacor!C$4) -> 36 | D5: =+COUNTIFS(Dados!$B:$B,Anacor!$B5,Dados!$C:$C,Anacor!D$4) -> 20 | E5: =+COUNTIFS(Dados!$B:$B,Anacor!$B5,Dados!$C:$C,Anacor!E$4) -> 2 | F5: =+SUM(C5:E5) -> 58
B6: Conservador | C6: =+COUNTIFS(Dados!$B:$B,Anacor!$B6,Dados!$C:$C,Anacor!C$4) -> 5 | D6: =+COUNTIFS(Dados!$B:$B,Anacor!$B6,Dados!$C:$C,Anacor!D$4) -> 4 | E6: =+COUNTIFS(Dados!$B:$B,Anacor!$B6,Dados!$C:$C,Anacor!E$4) -> 8 | F6: =+SUM(C6:E6) -> 17
B7: Moderado | C7: =+COUNTIFS(Dados!$B:$B,Anacor!$B7,Dados!$C:$C,Anacor!C$4) -> 4 | D7: =+COUNTIFS(Dados!$B:$B,Anacor!$B7,Dados!$C:$C,Anacor!D$4) -> 16 | E7: =+COUNTIFS(Dados!$B:$B,Anacor!$B7,Dados!$C:$C,Anacor!E$4) -> 5 | F7: =+SUM(C7:E7) -> 25
B8: Total | C8: =+SUM(C5:C7) -> 45 | D8: =+SUM(D5:D7) -> 40 | E8: =+SUM(E5:E7) -> 15 | F8: =+SUM(F5:F7) -> 100
A11: Frequências absolutas esperadas
C13: Tipo de Aplicação
C14: Ações | D14: CDB | E14: Poupança
A15: Perfil | B15: Agressivo | C15: =($F5*C$8)/$F$8 -> 26.1 | D15: =($F5*D$8)/$F$8 -> 23.2 | E15: =($F5*E$8)/$F$8 -> 8.7
B16: Conservador | C16: =($F6*C$8)/$F$8 -> 7.65 | D16: =($F6*D$8)/$F$8 -> 6.8 | E16: =($F6*E$8)/$F$8 -> 2.55
B17: Moderado | C17: =($F7*C$8)/$F$8 -> 11.25 | D17: =($F7*D$8)/$F$8 -> 10 | E17: =($F7*E$8)/$F$8 -> 3.75
A20: Resíduos
C22: Tipo de Aplicação
C23: Ações | D23: CDB | E23: Poupança
A24: Perfil | B24: Agressivo | C24: =+C5-C15 -> 9.9 | D24: =+D5-D15 -> -3.2 | E24: =+E5-E15 -> -6.7
B25: Conservador | C25: =+C6-C16 -> -2.65 | D25: =+D6-D16 -> -2.8 | E25: =+E6-E16 -> 5.45
B26: Moderado | C26: =+C7-C17 -> -7.25 | D26: =+D7-D17 -> 6 | E26: =+E7-E17 -> 1.25
A29: Valores χ²
C31: Tipo de Aplicação
C32: Ações | D32: CDB | E32: Poupança
A33: Perfil | B33: Agressivo | C33: =(C24^2)/C15 -> 3.7551724 | D33: =(D24^2)/D15 -> 0.44137931 | E33: =(E24^2)/E15 -> 5.1597701
B34: Conservador | C34: =(C25^2)/C16 -> 0.91797386 | D34: =(D25^2)/D16 -> 1.1529412 | E34: =(E25^2)/E16 -> 11.648039
B35: Moderado | C35: =(C26^2)/C17 -> 4.6722222 | D35: =(D26^2)/D17 -> 3.6 | E35: =(E26^2)/E17 -> 0.41666667
B37: χ² Total | C37: =+SUM(C33:E35) -> 31.764165
B38: p-valor | C38: =CHIDIST(C37,4) -> 2.1375941e-06
B39: nota: no exemplo, são 4 graus de liberdade (I-1)x(J-1).
A42: Resíduos padronizados
C44: Tipo de Aplicação
C45: Ações | D45: CDB | E45: Poupança
A46: Perfil | B46: Agressivo | C46: =+C24/SQRT(C15) -> 1.9378267 | D46: =+D24/SQRT(D15) -> -0.66436384 | E46: =+E24/SQRT(E15) -> -2.2715127
B47: Conservador | C47: =+C25/SQRT(C16) -> -0.95810952 | D47: =+D25/SQRT(D16) -> -1.073751 | E47: =+E25/SQRT(E16) -> 3.4129224
B48: Moderado | C48: =+C26/SQRT(C17) -> -2.1615324 | D48: =+D26/SQRT(D17) -> 1.8973666 | E48: =+E26/SQRT(E17) -> 0.64549722
A51: Resíduos padronizados ajustados
C53: Tipo de Aplicação
C54: Ações | D54: CDB | E54: Poupança
A55: Perfil | B55: Agressivo | C55: =+C46/SQRT((1-(C$8/$F$8))*(1-($F5/$F$8))) -> 4.0318926 | D55: =+D46/SQRT((1-(D$8/$F$8))*(1-($F5/$F$8))) -> -1.3234444 | E55: =+E46/SQRT((1-(E$8/$F$8))*(1-($F5/$F$8))) -> -3.8017282
B56: Conservador | C56: =+C47/SQRT((1-(C$8/$F$8))*(1-($F6/$F$8))) -> -1.4180605 | D56: =+D47/SQRT((1-(D$8/$F$8))*(1-($F6/$F$8))) -> -1.5215594 | E56: =+E47/SQRT((1-(E$8/$F$8))*(1-($F6/$F$8))) -> 4.0632908
B57: Moderado | C57: =+C48/SQRT((1-(C$8/$F$8))*(1-($F7/$F$8))) -> -3.3655013 | D57: =+D48/SQRT((1-(D$8/$F$8))*(1-($F7/$F$8))) -> 2.8284271 | E57: =+E48/SQRT((1-(E$8/$F$8))*(1-($F7/$F$8))) -> 0.80845208
...
